<?xml version="1.0" encoding="UTF-8"?>
<testng-results skipped="0" failed="3" ignored="7" total="10" passed="0">
  <reporter-output>
  </reporter-output>
  <suite name="Default suite" duration-ms="22640" started-at="2018-06-15T09:19:31Z" finished-at="2018-06-15T09:19:53Z">
    <groups>
      <group name="CountAll">
        <method signature="InfoSummaryTests.noareaCount()[pri:3, instance:com.test.suit.discover.InfoSummaryTests@4678c730]" name="noareaCount" class="com.test.suit.discover.InfoSummaryTests"/>
        <method signature="InfoSummaryTests.rbmeterCount()[pri:2, instance:com.test.suit.discover.InfoSummaryTests@4678c730]" name="rbmeterCount" class="com.test.suit.discover.InfoSummaryTests"/>
        <method signature="InfoSummaryTests.rmmeterCount()[pri:1, instance:com.test.suit.discover.InfoSummaryTests@4678c730]" name="rmmeterCount" class="com.test.suit.discover.InfoSummaryTests"/>
      </group> <!-- CountAll -->
    </groups>
    <test name="Default test" duration-ms="22640" started-at="2018-06-15T09:19:31Z" finished-at="2018-06-15T09:19:53Z">
      <class name="com.test.suit.discover.InfoSummaryTests">
        <test-method status="PASS" signature="declare()[pri:0, instance:com.test.suit.discover.InfoSummaryTests@4678c730]" name="declare" is-config="true" duration-ms="22613" started-at="2018-06-15T09:19:31Z" finished-at="2018-06-15T09:19:53Z">
          <reporter-output>
          </reporter-output>
        </test-method> <!-- declare -->
        <test-method status="PASS" signature="beforeGroup()[pri:0, instance:com.test.suit.discover.InfoSummaryTests@4678c730]" name="beforeGroup" is-config="true" duration-ms="0" started-at="2018-06-15T09:19:53Z" finished-at="2018-06-15T09:19:53Z">
          <reporter-output>
          </reporter-output>
        </test-method> <!-- beforeGroup -->
        <test-method status="FAIL" signature="rmmeterCount()[pri:1, instance:com.test.suit.discover.InfoSummaryTests@4678c730]" name="rmmeterCount" duration-ms="6" started-at="2018-06-15T09:19:53Z" finished-at="2018-06-15T09:19:53Z">
          <exception class="java.lang.AssertionError">
            <message>
              <![CDATA[expected [6712] but found [6868]]]>
            </message>
            <full-stacktrace>
              <![CDATA[java.lang.AssertionError: expected [6712] but found [6868]
at org.testng.Assert.fail(Assert.java:96)
at org.testng.Assert.failNotEquals(Assert.java:776)
at org.testng.Assert.assertEqualsImpl(Assert.java:137)
at org.testng.Assert.assertEquals(Assert.java:118)
at org.testng.Assert.assertEquals(Assert.java:442)
at com.test.suit.discover.InfoSummaryTests.rmmeterCount(InfoSummaryTests.java:49)
at sun.reflect.NativeMethodAccessorImpl.invoke0(Native Method)
at sun.reflect.NativeMethodAccessorImpl.invoke(Unknown Source)
at sun.reflect.DelegatingMethodAccessorImpl.invoke(Unknown Source)
at java.lang.reflect.Method.invoke(Unknown Source)
at org.testng.internal.MethodInvocationHelper.invokeMethod(MethodInvocationHelper.java:124)
at org.testng.internal.Invoker.invokeMethod(Invoker.java:580)
at org.testng.internal.Invoker.invokeTestMethod(Invoker.java:716)
at org.testng.internal.Invoker.invokeTestMethods(Invoker.java:988)
at org.testng.internal.TestMethodWorker.invokeTestMethods(TestMethodWorker.java:125)
at org.testng.internal.TestMethodWorker.run(TestMethodWorker.java:109)
at org.testng.TestRunner.privateRun(TestRunner.java:648)
at org.testng.TestRunner.run(TestRunner.java:505)
at org.testng.SuiteRunner.runTest(SuiteRunner.java:455)
at org.testng.SuiteRunner.runSequentially(SuiteRunner.java:450)
at org.testng.SuiteRunner.privateRun(SuiteRunner.java:415)
at org.testng.SuiteRunner.run(SuiteRunner.java:364)
at org.testng.SuiteRunnerWorker.runSuite(SuiteRunnerWorker.java:52)
at org.testng.SuiteRunnerWorker.run(SuiteRunnerWorker.java:84)
at org.testng.TestNG.runSuitesSequentially(TestNG.java:1208)
at org.testng.TestNG.runSuitesLocally(TestNG.java:1137)
at org.testng.TestNG.runSuites(TestNG.java:1049)
at org.testng.TestNG.run(TestNG.java:1017)
at org.testng.remote.AbstractRemoteTestNG.run(AbstractRemoteTestNG.java:114)
at org.testng.remote.RemoteTestNG.initAndRun(RemoteTestNG.java:251)
at org.testng.remote.RemoteTestNG.main(RemoteTestNG.java:77)
]]>
            </full-stacktrace>
          </exception> <!-- java.lang.AssertionError -->
          <reporter-output>
          </reporter-output>
        </test-method> <!-- rmmeterCount -->
        <test-method status="FAIL" signature="rbmeterCount()[pri:2, instance:com.test.suit.discover.InfoSummaryTests@4678c730]" name="rbmeterCount" duration-ms="2" started-at="2018-06-15T09:19:53Z" finished-at="2018-06-15T09:19:53Z">
          <exception class="java.lang.AssertionError">
            <message>
              <![CDATA[expected [12025] but found [12417]]]>
            </message>
            <full-stacktrace>
              <![CDATA[java.lang.AssertionError: expected [12025] but found [12417]
at org.testng.Assert.fail(Assert.java:96)
at org.testng.Assert.failNotEquals(Assert.java:776)
at org.testng.Assert.assertEqualsImpl(Assert.java:137)
at org.testng.Assert.assertEquals(Assert.java:118)
at org.testng.Assert.assertEquals(Assert.java:442)
at com.test.suit.discover.InfoSummaryTests.rbmeterCount(InfoSummaryTests.java:54)
at sun.reflect.NativeMethodAccessorImpl.invoke0(Native Method)
at sun.reflect.NativeMethodAccessorImpl.invoke(Unknown Source)
at sun.reflect.DelegatingMethodAccessorImpl.invoke(Unknown Source)
at java.lang.reflect.Method.invoke(Unknown Source)
at org.testng.internal.MethodInvocationHelper.invokeMethod(MethodInvocationHelper.java:124)
at org.testng.internal.Invoker.invokeMethod(Invoker.java:580)
at org.testng.internal.Invoker.invokeTestMethod(Invoker.java:716)
at org.testng.internal.Invoker.invokeTestMethods(Invoker.java:988)
at org.testng.internal.TestMethodWorker.invokeTestMethods(TestMethodWorker.java:125)
at org.testng.internal.TestMethodWorker.run(TestMethodWorker.java:109)
at org.testng.TestRunner.privateRun(TestRunner.java:648)
at org.testng.TestRunner.run(TestRunner.java:505)
at org.testng.SuiteRunner.runTest(SuiteRunner.java:455)
at org.testng.SuiteRunner.runSequentially(SuiteRunner.java:450)
at org.testng.SuiteRunner.privateRun(SuiteRunner.java:415)
at org.testng.SuiteRunner.run(SuiteRunner.java:364)
at org.testng.SuiteRunnerWorker.runSuite(SuiteRunnerWorker.java:52)
at org.testng.SuiteRunnerWorker.run(SuiteRunnerWorker.java:84)
at org.testng.TestNG.runSuitesSequentially(TestNG.java:1208)
at org.testng.TestNG.runSuitesLocally(TestNG.java:1137)
at org.testng.TestNG.runSuites(TestNG.java:1049)
at org.testng.TestNG.run(TestNG.java:1017)
at org.testng.remote.AbstractRemoteTestNG.run(AbstractRemoteTestNG.java:114)
at org.testng.remote.RemoteTestNG.initAndRun(RemoteTestNG.java:251)
at org.testng.remote.RemoteTestNG.main(RemoteTestNG.java:77)
]]>
            </full-stacktrace>
          </exception> <!-- java.lang.AssertionError -->
          <reporter-output>
          </reporter-output>
        </test-method> <!-- rbmeterCount -->
        <test-method status="FAIL" signature="noareaCount()[pri:3, instance:com.test.suit.discover.InfoSummaryTests@4678c730]" name="noareaCount" duration-ms="1" started-at="2018-06-15T09:19:53Z" finished-at="2018-06-15T09:19:53Z">
          <exception class="java.lang.AssertionError">
            <message>
              <![CDATA[expected [1948] but found [30585]]]>
            </message>
            <full-stacktrace>
              <![CDATA[java.lang.AssertionError: expected [1948] but found [30585]
at org.testng.Assert.fail(Assert.java:96)
at org.testng.Assert.failNotEquals(Assert.java:776)
at org.testng.Assert.assertEqualsImpl(Assert.java:137)
at org.testng.Assert.assertEquals(Assert.java:118)
at org.testng.Assert.assertEquals(Assert.java:442)
at com.test.suit.discover.InfoSummaryTests.noareaCount(InfoSummaryTests.java:59)
at sun.reflect.NativeMethodAccessorImpl.invoke0(Native Method)
at sun.reflect.NativeMethodAccessorImpl.invoke(Unknown Source)
at sun.reflect.DelegatingMethodAccessorImpl.invoke(Unknown Source)
at java.lang.reflect.Method.invoke(Unknown Source)
at org.testng.internal.MethodInvocationHelper.invokeMethod(MethodInvocationHelper.java:124)
at org.testng.internal.Invoker.invokeMethod(Invoker.java:580)
at org.testng.internal.Invoker.invokeTestMethod(Invoker.java:716)
at org.testng.internal.Invoker.invokeTestMethods(Invoker.java:988)
at org.testng.internal.TestMethodWorker.invokeTestMethods(TestMethodWorker.java:125)
at org.testng.internal.TestMethodWorker.run(TestMethodWorker.java:109)
at org.testng.TestRunner.privateRun(TestRunner.java:648)
at org.testng.TestRunner.run(TestRunner.java:505)
at org.testng.SuiteRunner.runTest(SuiteRunner.java:455)
at org.testng.SuiteRunner.runSequentially(SuiteRunner.java:450)
at org.testng.SuiteRunner.privateRun(SuiteRunner.java:415)
at org.testng.SuiteRunner.run(SuiteRunner.java:364)
at org.testng.SuiteRunnerWorker.runSuite(SuiteRunnerWorker.java:52)
at org.testng.SuiteRunnerWorker.run(SuiteRunnerWorker.java:84)
at org.testng.TestNG.runSuitesSequentially(TestNG.java:1208)
at org.testng.TestNG.runSuitesLocally(TestNG.java:1137)
at org.testng.TestNG.runSuites(TestNG.java:1049)
at org.testng.TestNG.run(TestNG.java:1017)
at org.testng.remote.AbstractRemoteTestNG.run(AbstractRemoteTestNG.java:114)
at org.testng.remote.RemoteTestNG.initAndRun(RemoteTestNG.java:251)
at org.testng.remote.RemoteTestNG.main(RemoteTestNG.java:77)
]]>
            </full-stacktrace>
          </exception> <!-- java.lang.AssertionError -->
          <reporter-output>
          </reporter-output>
        </test-method> <!-- noareaCount -->
      </class> <!-- com.test.suit.discover.InfoSummaryTests -->
    </test> <!-- Default test -->
  </suite> <!-- Default suite -->
</testng-results>
